Workbook

Sheet Data_Collection
A1: Date | B1: Day | C1: Plant-ID | D1: Total Fresh Weight (g) | E1: Baseline (g) | F1: New Fresh Weight (g) | G1: Median Fresh Weight (g) | H1: Average Fresh Weight (g)
B2: 0 | C2: 6 | D2: 29.1 | E2: 25.22 | F2: =SUM(D2-E2) -> 3.88
B3: 0 | C3: 4 | D3: 29.3 | E3: 25.22 | F3: =SUM(D3-E3) -> 4.08
B4: 0 | C4: 9 | D4: 29.6 | E4: 25.22 | F4: =SUM(D4-E4) -> 4.38
B5: 0 | C5: 1 | D5: 29.7 | E5: 25.22 | F5: =SUM(D5-E5) -> 4.48
B6: 0 | C6: 8 | D6: 29.8 | E6: 25.22 | F6: =SUM(D6-E6) -> 4.58
B7: 0 | C7: 2 | D7: 30.1 | E7: 25.22 | F7: =SUM(D7-E7) -> 4.88 | G7: =SUM(F7+F6)/2 -> 4.73 | H7: =AVERAGE(F2:F11) -> 4.89
B8: 0 | C8: 5 | D8: 30.2 | E8: 25.22 | F8: =SUM(D8-E8) -> 4.98
B9: 0 | C9: 7 | D9: 30.4 | E9: 25.22 | F9: =SUM(D9-E9) -> 5.18
B10: 0 | C10: 10 | D10: 31.1 | E10: 25.22 | F10: =SUM(D10-E10) -> 5.88
B11: 0 | C11: 3 | D11: 31.8 | E11: 25.22 | F11: =SUM(D11-E11) -> 6.58
B13: 4 | C13: 6 | D13: 33.1 | E13: 25.22 | F13: =SUM(D13-E13) -> 7.88
B14: 4 | C14: 2 | D14: 36.3 | E14: 25.22 | F14: =SUM(D14-E14) -> 11.08
B15: 4 | C15: 8 | D15: 36.5 | E15: 25.22 | F15: =SUM(D15-E15) -> 11.28
B16: 4 | C16: 9 | D16: 36.9 | E16: 25.22 | F16: =SUM(D16-E16) -> 11.68
B17: 4 | C17: 1 | D17: 38.1 | E17: 25.22 | F17: =SUM(D17-E17) -> 12.88
B18: 4 | C18: 5 | D18: 38.5 | E18: 25.22 | F18: =SUM(D18-E18) -> 13.28 | G18: =SUM(F18+F17)/2 -> 13.08 | H18: =AVERAGE(F13:F22) -> 12.76
B19: 4 | C19: 4 | D19: 39.2 | E19: 25.22 | F19: =SUM(D19-E19) -> 13.98
B20: 4 | C20: 7 | D20: 39.2 | E20: 25.22 | F20: =SUM(D20-E20) -> 13.98
B21: 4 | C21: 10 | D21: 39.9 | E21: 25.22 | F21: =SUM(D21-E21) -> 14.68
B22: 4 | C22: 3 | D22: 42.1 | E22: 25.22 | F22: =SUM(D22-E22) -> 16.88
B24: 8 | C24: 6 | D24: 40.1 | E24: 25.22 | F24: =SUM(D24-E24) -> 14.88
B25: 8 | C25: 2 | D25: 43.4 | E25: 25.22 | F25: =SUM(D25-E25) -> 18.18
B26: 8 | C26: 8 | D26: 43.6 | E26: 25.22 | F26: =SUM(D26-E26) -> 18.38
B27: 8 | C27: 1 | D27: 44.3 | E27: 25.22 | F27: =SUM(D27-E27) -> 19.08
B28: 8 | C28: 6 | D28: 45 | E28: 25.22 | F28: =SUM(D28-E28) -> 19.78
B29: 8 | C29: 5 | D29: 45.1 | E29: 25.22 | F29: =SUM(D29-E29) -> 19.88 | G29: =SUM(F29+F28)/2 -> 19.83 | H29: =AVERAGE(F24:F33) -> 19.75
B30: 8 | C30: 4 | D30: 46 | E30: 25.22 | F30: =SUM(D30-E30) -> 20.78
B31: 8 | C31: 7 | D31: 46.2 | E31: 25.22 | F31: =SUM(D31-E31) -> 20.98
B32: 8 | C32: 9 | D32: 46.8 | E32: 25.22 | F32: =SUM(D32-E32) -> 21.58
B33: 8 | C33: 3 | D33: 49.2 | E33: 25.22 | F33: =SUM(D33-E33) -> 23.98
B35: 12 | C35: 6 | D35: 47 | E35: 25.22 | F35: =SUM(D35-E35) -> 21.78
B36: 12 | C36: 5 | D36: 51 | E36: 25.22 | F36: =SUM(D36-E36) -> 25.78
B37: 12 | C37: 1 | D37: 52 | E37: 25.22 | F37: =SUM(D37-E37) -> 26.78
B38: 12 | C38: 8 | D38: 52 | E38: 25.22 | F38: =SUM(D38-E38) -> 26.78
B39: 12 | C39: 7 | D39: 52 | E39: 25.22 | F39: =SUM(D39-E39) -> 26.78
B40: 12 | C40: 2 | D40: 53 | E40: 25.22 | F40: =SUM(D40-E40) -> 27.78 | G40: =SUM(F40+F39)/2 -> 27.28 | H40: =AVERAGE(F35:F44) -> 27.58
B41: 12 | C41: 9 | D41: 53 | E41: 25.22 | F41: =SUM(D41-E41) -> 27.78
B42: 12 | C42: 4 | D42: 55 | E42: 25.22 | F42: =SUM(D42-E42) -> 29.78
B43: 12 | C43: 10 | D43: 55 | E43: 25.22 | F43: =SUM(D43-E43) -> 29.78
...

Sheet Targets
A1: Targets Days. | B1: FW_Target_Mid_g | C1: FW_Target_Low_g | D1: FW_Target_High_g
A2: 0 | B2: 3.5 | C2: 3 | D2: 4
A3: 4 | B3: 8.8 | C3: 7.5 | D3: 10.1
A4: 8 | B4: 22.2 | C4: 18.9 | D4: 25.5
A5: 12 | B5: 56 | C5: 47.6 | D5: 64.4
A6: 16 | B6: 98.8 | C6: 88.9 | D6: 108.6
A7: 20 | B7: 141.5 | C7: 127.4 | D7: 155.7
A8: 24 | B8: 184.3 | C8: 165.8 | D8: 202.7
A9: 28 | B9: 227 | C9: 211.1 | D9: 242.9
I13: 219
A27: Date | B27: Day | C27: Median Net Fresh Weight | D27: Target Fresh Weight
B28: 0 | C28: 4.7 | D28: 3.5
B29: 4 | C29: 13.1 | D29: 8.8
B30: 8 | C30: 19.8 | D30: 22.2
B31: 12 | C31: 27.3 | D31: 56 | E31: Change in light
B32: 16 | C32: 42.3 | D32: 98.8
B33: 20 | C33: 80.8 | D33: 141.5
B34: 24 | C34: 139.3 | D34: 184.3
B35: 28 | C35: 219.8 | D35: 227

Sheet EC_Log
A1: Date | B1: Day | C1: Target Fresh Weight Range | D1: Target Mid Range | E1: Actual Mid Range | F1: Status | G1: EC Range. Now | H1: New EC | I1: Note
C2: 3.0 - 4.0 | D2: 3.5 | E2: 4.7 | F2: Above | G2: 1.2 - 1.4 | I2: Initial
C3: 7.5 - 10.1 | D3: 8.8 | E3: 13.1 | F3: Above | G3: 1.2 - 1.4
C4: 18.9 - 25.5 | D4: 22.2 | E4: 19.8 | F4: Below | G4: 1.2 - 1.4 | H4: 1.4 - 1.6 | I4: EC Change
C5: 47.6 - 64.4 | D5: 56 | E5: 27.3 | F5: Below | G5: 1.4-1.6 | H5: 1.6-1.8 | I5: EC Change
C6: 88.9 - 108.6 | D6: 98.8 | E6: 42.3 | F6: Below | G6: 1.6-1.8
C7: 127.4 - 155.7 | D7: 141.5 | E7: 80.8 | F7: Below | G7: 1.6-1.8
C8: 165.8 - 202.7 | D8: 184.3 | E8: 139.3 | F8: Below | G8: 1.8-2.0
C9: 211.1 - 242.9 | D9: 227 | E9: 219.8 | F9: Within | G9: 1.8-2.0

Sheet Aggregations
A1: Day | B1: Median_FW_g | C1: Min_FW_g | D1: Max_FW_g | E1: FW_Target_Low_g | F1: FW_Target_High_g | G1: In_Band?
A2: 0 | B2: =MEDIAN(IF($B$3:$B$92=0,$F$3:$F$92)) -> #VALUE! | C2: =MIN(IF($B$3:$B$92=0,$F$3:$F$92)) -> #VALUE! | D2: =MAX(IF($B$3:$B$92=0,$F$3:$F$92)) -> #VALUE! | E2: {=_xlfn.XLOOKUP(A2,Targets!A:A,Targets!C:C,"")} -> 3 | F2: {=_xlfn.XLOOKUP(A2,Targets!A:A,Targets!D:D,"")} -> 4 | G2: =IF(AND(E2<>"",F2<>"",B2>=E2,B2<=F2),"YES","NO") -> #VALUE!
A3: 4 | B3: =MEDIAN(IF($B$3:$B$92=4,$F$3:$F$92)) -> 0 | C3: =MIN(IF($B$3:$B$92=4,$F$3:$F$92)) -> 0 | D3: =MAX(IF($B$3:$B$92=4,$F$3:$F$92)) -> 0 | E3: {=_xlfn.XLOOKUP(A3,Targets!A:A,Targets!C:C,"")} -> 7.5 | F3: {=_xlfn.XLOOKUP(A3,Targets!A:A,Targets!D:D,"")} -> 10.1 | G3: =IF(AND(E3<>"",F3<>"",B3>=E3,B3<=F3),"YES","NO") -> 0
A4: 6 | B4: =MEDIAN(IF($B$3:$B$92=6,$F$3:$F$92)) -> 0 | C4: =MIN(IF($B$3:$B$92=6,$F$3:$F$92)) -> 0 | D4: =MAX(IF($B$3:$B$92=6,$F$3:$F$92)) -> 0 | E4: {=_xlfn.XLOOKUP(A4,Targets!A:A,Targets!C:C,"")} | F4: {=_xlfn.XLOOKUP(A4,Targets!A:A,Targets!D:D,"")} | G4: =IF(AND(E4<>"",F4<>"",B4>=E4,B4<=F4),"YES","NO") -> 0
A5: 8 | B5: =MEDIAN(IF($B$3:$B$92=8,$F$3:$F$92)) -> 0 | C5: =MIN(IF($B$3:$B$92=8,$F$3:$F$92)) -> 0 | D5: =MAX(IF($B$3:$B$92=8,$F$3:$F$92)) -> 0 | E5: {=_xlfn.XLOOKUP(A5,Targets!A:A,Targets!C:C,"")} -> 18.9 | F5: {=_xlfn.XLOOKUP(A5,Targets!A:A,Targets!D:D,"")} -> 25.5 | G5: =IF(AND(E5<>"",F5<>"",B5>=E5,B5<=F5),"YES","NO") -> 0
A6: 12 | B6: =MEDIAN(IF($B$3:$B$92=12,$F$3:$F$92)) -> 0 | C6: =MIN(IF($B$3:$B$92=12,$F$3:$F$92)) -> 0 | D6: =MAX(IF($B$3:$B$92=12,$F$3:$F$92)) -> 0 | E6: {=_xlfn.XLOOKUP(A6,Targets!A:A,Targets!C:C,"")} -> 47.6 | F6: {=_xlfn.XLOOKUP(A6,Targets!A:A,Targets!D:D,"")} -> 64.4 | G6: =IF(AND(E6<>"",F6<>"",B6>=E6,B6<=F6),"YES","NO") -> 0
A7: 16 | B7: =MEDIAN(IF($B$3:$B$92=16,$F$3:$F$92)) -> 0 | C7: =MIN(IF($B$3:$B$92=16,$F$3:$F$92)) -> 0 | D7: =MAX(IF($B$3:$B$92=16,$F$3:$F$92)) -> 0 | E7: {=_xlfn.XLOOKUP(A7,Targets!A:A,Targets!C:C,"")} -> 88.9 | F7: {=_xlfn.XLOOKUP(A7,Targets!A:A,Targets!D:D,"")} -> 108.6 | G7: =IF(AND(E7<>"",F7<>"",B7>=E7,B7<=F7),"YES","NO") -> 0
A8: 20 | B8: =MEDIAN(IF($B$3:$B$92=20,$F$3:$F$92)) -> 0 | C8: =MIN(IF($B$3:$B$92=20,$F$3:$F$92)) -> 0 | D8: =MAX(IF($B$3:$B$92=20,$F$3:$F$92)) -> 0 | E8: {=_xlfn.XLOOKUP(A8,Targets!A:A,Targets!C:C,"")} -> 127.4 | F8: {=_xlfn.XLOOKUP(A8,Targets!A:A,Targets!D:D,"")} -> 155.7 | G8: =IF(AND(E8<>"",F8<>"",B8>=E8,B8<=F8),"YES","NO") -> 0
A9: 24 | B9: =MEDIAN(IF($B$3:$B$92=24,$F$3:$F$92)) -> 0 | C9: =MIN(IF($B$3:$B$92=24,$F$3:$F$92)) -> 0 | D9: =MAX(IF($B$3:$B$92=24,$F$3:$F$92)) -> 0 | E9: {=_xlfn.XLOOKUP(A9,Targets!A:A,Targets!C:C,"")} -> 165.8 | F9: {=_xlfn.XLOOKUP(A9,Targets!A:A,Targets!D:D,"")} -> 202.7 | G9: =IF(AND(E9<>"",F9<>"",B9>=E9,B9<=F9),"YES","NO") -> 0
A10: 28 | B10: =MEDIAN(IF($B$3:$B$92=28,$F$3:$F$92)) -> 0 | C10: =MIN(IF($B$3:$B$92=28,$F$3:$F$92)) -> 0 | D10: =MAX(IF($B$3:$B$92=28,$F$3:$F$92)) -> 0 | E10: {=_xlfn.XLOOKUP(A10,Targets!A:A,Targets!C:C,"")} -> 211.1 | F10: {=_xlfn.XLOOKUP(A10,Targets!A:A,Targets!D:D,"")} -> 242.9 | G10: =IF(AND(E10<>"",F10<>"",B10>=E10,B10<=F10),"YES","NO") -> 0
